Workbook
Name base_threshold: 'ICER Interpretation'!$F$10
Name cost_ANG: 'Costs & QALY'!$B$65
Name cost_CABG: 'Costs & QALY'!$B$66
Name cost_EST: 'Costs & QALY'!$B$64
Name cost_MM_moderate: 'Costs & QALY'!$B$69
Name cost_MM_postCABG: 'Costs & QALY'!$B$67
Name cost_MM_severe: 'Costs & QALY'!$B$68
Name cost_NT: 'Costs & QALY'!$B$69
Name p_AliveGiivenMVDCABG: Inputs!$C$53
Name p_AliveGivenMVDANG: Inputs!$B$53
Name p_AliveGivenSVDANG: Inputs!$B$52
Name p_AliveGivenSVDCABG: Inputs!$C$52
Name p_CABGfailMVD: Inputs!$C$59
Name p_CABGfailSVD: Inputs!$B$59
Name p_CABGsucessMVD: Inputs!$C$58
Name p_CABGsucessMVDCABG: Inputs!$C$58
Name p_CABGsucessSVD: Inputs!$B$52
Name p_DaethGivenMVDCABG: Inputs!$C$47
Name p_DeathGivenMVDANG: Inputs!$B$47
Name p_DeathGivenMVDCABG: Inputs!$C$47
Name p_DeathGivenSVDANG: Inputs!$B$46
Name p_FalseNegative: Inputs!$B$18
Name p_FalsePosiive: Inputs!$C$17
Name p_FalsePosiive_est: Inputs!$C$17
Name p_FalsePosiiveEST: Inputs!$C$17
Name p_healthy: Inputs!$B$7
Name p_HealthyGivenNegative: Inputs!$C$28
Name p_HealthyGivenNegativeCABG: Inputs!$C$42
Name p_HealthyGivenPositive: Inputs!$C$27
Name p_HealthyGivenPositiveCABG: Inputs!$C$41
Name p_MVD: Inputs!$B$12
Name p_MVDgivenS: Inputs!$B$10
Name p_sick: Inputs!$B$6
Name p_SickgivenNegative: Inputs!$B$28
Name p_SickgivenNegativeCABG: Inputs!$B$42
Name p_SickgivenPositive: Inputs!$B$27
Name p_SickgivenPositiveCABG: Inputs!$B$41
Name p_successSVDCABG: Inputs!$B$58
Name p_sVD: Inputs!$B$11
Name p_sVDgivenS: Inputs!$B$9
Name p_T: Inputs!$B$17
Name p_TestNegative: Inputs!$E$23
Name p_TestNegativeANG: Inputs!$E$38
Name p_TestPositive: Inputs!$E$22
Name p_TestPositiveANG: Inputs!$E$37
Name p_TrueNegative: Inputs!$C$18
Name p_TruePositive: Inputs!$B$17
Name p_TruePositive_EST: Inputs!$B$17

Sheet Title

Sheet Introduction

Sheet Inputs
A3: Probabilitiies
A5: Prior Proabilities
A6: p{s} | B6: 0.9
A7: p{h} | B7: =1-B6 -> 0.1
A9: p(SVD|S] | B9: 0.1
A10: P[MVD|S] | B10: 0.9
A11: p[SVD] | B11: =B9*B6 -> 0.09
A12: p[MVD] | B12: =B10*B6 -> 0.81
A14: For EST:
A15: Conditional Probabilities (p[T+|S])
B16: Sick (s) | C16: Healthy (h)
A17: Test +ve | B17: 0.85 | C17: =1-C18 -> 0.1
A18: Test -ve | B18: =1-B17 -> 0.15 | C18: 0.9
A20: Joint Proabilities (p[T+,s] = p[s].p[T+|s)
B21: sick(s) | C21: Healthy (h)
A22: Test +ve | B22: =B6*B17 -> 0.765 | C22: =B7*C17 -> 0.01 | D22: p[T+]= | E22: =B22+C22 -> 0.775 | M22: `
A23: Test -ve | B23: =B6*B18 -> 0.135 | C23: =B7*C18 -> 0.09 | D23: p[T-]= | E23: =B23+C23 -> 0.225
A25: Predictive Values(p[s|+ve) = p[T+, s]/p[T+ )
B26: sick (s) | C26: Healthy (h)
A27: Test +ve | B27: =B22/E22 -> 0.98709677 | C27: =C22/E22 -> 0.012903226 | D27: =B27+C27 -> 1
A28: Test -ve | B28: =B23/E23 -> 0.6 | C28: =C23/E23 -> 0.4 | D28: =B28+C28 -> 1
A30: For ANG:
A31: Conditional Probabilities (p[T+|S])
B32: Sick (s) | C32: Healthy (h)
A33: Test +ve | B33: 1 | C33: =1-C34 -> 0
A34: Test -ve | B34: =1-B33 -> 0 | C34: 1 | G34: `
A35: Joint Proabilities (p[T+,s] = p[s].p[T+|s)
B36: sick(s) | C36: Healthy (h)
A37: Test +ve | B37: =B33*B6 -> 0.9 | C37: =C33*B7 -> 0 | D37: p[T+]= | E37: =B37+C37 -> 0.9
A38: Test -ve | B38: =B34*B6 -> 0 | C38: =C34*B7 -> 0.1 | D38: p[T-]= | E38: =B38+C38 -> 0.1
A39: Predictive Values(p[s|T+) = p[T+, s]/p[T+ )
B40: sick (s) | C40: Healthy (h)
A41: Test +ve | B41: =B37/E37 -> 1 | C41: =C37/E37 -> 0
A42: Test -ve | B42: =B38/E38 -> 0 | C42: =C38/E38 -> 1
A44: Probabilities of Death (p[D|SVD]
B45: ANG | C45: CABG
A46: p(SVD) | B46: 0.0003 | C46: 0.03
A47: p(MVD) | B47: 0.001 | C47: 0.08
A48: p[no disease] | B48: 0.0002
A50: Probabilities of Alive (p[A|SVD])
...

Sheet Costs & QALY
A1: QALY CALCULATION
A2: ROSSER MATRIX
A3: Disability | B3: A | C3: B | D3: C | E3: D
A4: I | B4: 1 | C4: 0.995 | D4: 0.99 | E4: 0.967
A5: II | B5: 0.99 | C5: 0.986 | D5: 0.973 | E5: 0.932
A6: III | B6: 0.98 | C6: 0.972 | D6: 0.956 | E6: 0.912
A7: IV | B7: 0.964 | C7: 0.956 | D7: 0.942 | E7: 0.87
A8: V | B8: 0.946 | C8: 0.935 | D8: 0.9 | E8: 0.7
A9: VI | B9: 0.875 | C9: 0.845 | D9: 0.68 | E9: 0
A10: VII | B10: 0.677 | C10: 0.564 | D10: 0 | E10: -1.486
A11: VIII | B11: -1.028 | C11: - | D11: - | E11: -
A13: DISCOUNT FACTOR
A14: Discount Rate = | B14: 0.035
A17: Severe Pain> SVD> CABG | G17: Severe Pain>MVD>CABG
A18: Health States | B18: Disability/Stress level | C18: Utility Values | D18: Discounted QALY | G18: Health States | H18: Disability/Stress level | I18: Utility Values | J18: Discounted QALY
A19: 1 | B19: IA | C19: =B4 -> 1 | D19: =C19/((1+B$14)^A19) -> 0.96618357 | G19: 1 | H19: IB | I19: =C4 -> 0.995 | J19: =I19/((1+B$14)^G19) -> 0.96135266
A20: 2 | B20: IA | C20: =B4 -> 1 | D20: =C20/((1+B$14)^A20) -> 0.9335107 | G20: 2 | H20: IA | I20: =B4 -> 1 | J20: =I20/((1+B$14)^G20) -> 0.9335107
A21: 3 | B21: IA | C21: =B4 -> 1 | D21: =C21/((1+B$14)^A21) -> 0.90194271 | G21: 3 | H21: IIA | I21: =B5 -> 0.99 | J21: =I21/((1+B$14)^G21) -> 0.89292328
A22: 4 | B22: IIB | C22: =C5 -> 0.986 | D22: =C22/((1+B$14)^A22) -> 0.85924204 | G22: 4 | H22: IIB | I22: =C5 -> 0.986 | J22: =I22/((1+B$14)^G22) -> 0.85924204
A23: 5 | B23: IIB | C23: =C5 -> 0.986 | D23: =C23/((1+B$14)^A23) -> 0.83018554 | G23: 5 | H23: IIIB | I23: =C6 -> 0.972 | J23: =I23/((1+B$14)^G23) -> 0.81839792
A24: 6 | B24: IIB | C24: =C5 -> 0.986 | D24: =C24/((1+B$14)^A24) -> 0.80211164 | G24: 6 | H24: IVC | I24: =D7 -> 0.942 | J24: =I24/((1+B$14)^G24) -> 0.76631761
A25: 7 | B25: IIC | C25: =D5 -> 0.973 | D25: =C25/((1+B$14)^A25) -> 0.7647692 | G25: 7 | H25: IVC | I25: =D7 -> 0.942 | J25: =I25/((1+B$14)^G25) -> 0.74040348
A26: 8 | B26: IIIC | C26: =D6 -> 0.956 | D26: =C26/((1+B$14)^A26) -> 0.72599745 | G26: 8 | H26: VC | I26: =D8 -> 0.9 | J26: =I26/((1+B$14)^G26) -> 0.6834704
A27: 9 | B27: IIIC | C27: =D6 -> 0.956 | D27: =C27/((1+B$14)^A27) -> 0.70144681 | G27: 9 | H27: VID | I27: =E9 -> 0 | J27: =I27/((1+B$14)^G27) -> 0
A28: 10 | B28: IIIC | C28: =D6 -> 0.956 | D28: =C28/((1+B$14)^A28) -> 0.67772639 | G28: 10 | H28: VIID | I28: =E10 -> -1.486 | J28: =I28/((1+B$14)^G28) -> -1.0534534
C29: Total QALY | D29: =SUM(D19:D28) -> 8.163116 | I29: Total Qaly | J29: =SUM(J19:J28) -> 5.6021647
A32: Severe Pain> SVD> MM | G32: Severe Pain> MVD> MM
A33: Health States | B33: Disability/Stress level | C33: Utility Values | D33: Discounted QALY | G33: Health States | H33: Disability/Stress level | I33: Utility Values | J33: Discounted QALY
A34: 1 | B34: IIB | C34: =C5 -> 0.986 | D34: =C34/((1+B$14)^A34) -> 0.952657 | G34: 1 | H34: IIIC | I34: =D6 -> 0.956 | J34: =I34/((1+B$14)^G34) -> 0.9236715
A35: 2 | B35: IIB | C35: =C5 -> 0.986 | D35: =C35/((1+B$14)^A35) -> 0.92044155 | G35: 2 | H35: IIIC | I35: =D6 -> 0.956 | J35: =I35/((1+B$14)^G35) -> 0.89243623
A36: 3 | B36: IIIC | C36: =D6 -> 0.956 | D36: =C36/((1+B$14)^A36) -> 0.86225723 | G36: 3 | H36: IVC | I36: =D7 -> 0.942 | J36: =I36/((1+B$14)^G36) -> 0.84963003
A37: 4 | B37: IIIC | C37: =D6 -> 0.956 | D37: =C37/((1+B$14)^A37) -> 0.83309877 | G37: 4 | H37: IVD | I37: =E7 -> 0.87 | J37: =I37/((1+B$14)^G37) -> 0.75815474
A38: 5 | B38: IIIC | C38: =D6 -> 0.956 | D38: =C38/((1+B$14)^A38) -> 0.80492635 | G38: 5 | H38: VD | I38: =E8 -> 0.7 | J38: =I38/((1+B$14)^G38) -> 0.58938122
A39: 6 | B39: IVC | C39: =D7 -> 0.942 | D39: =C39/((1+B$14)^A39) -> 0.76631761 | I39: Toral QALY | J39: =SUM(J34:J38) -> 4.0132737
A40: 7 | B40: IVC | C40: =D7 -> 0.942 | D40: =C40/((1+B$14)^A40) -> 0.74040348
A41: 8 | B41: IVC | C41: =D7 -> 0.942 | D41: =C41/((1+B$14)^A41) -> 0.71536569
A42: 9 | B42: VD | C42: =E8 -> 0.7 | D42: =C42/((1+B$14)^A42) -> 0.51361168
A43: 10 | B43: VD | C43: =E8 -> 0.7 | D43: =C43/((1+B$14)^A43) -> 0.49624317
C44: Total QALY | D44: =SUM(D34:D43) -> 7.6053225
M46: Severe Pain>Healthy>No Treatment
...

Sheet The Decision Tree
P2: Different Strategy Strands for the Treatment of Severe Angina
AR13: P[SVD|S]
AR14: =p_sVDgivenS -> 0.1 | AT14: Cost | AU14: ='Costs & QALY'!C111 -> 1779.7535 | AV14: QALY | AW14: ='Costs & QALY'!D44 -> 7.6053225
AJ15: P[S|+VE] | AM15: EV | AN15: =AR14*AW14+AR18*AW18 -> 4.3724786
AJ16: =p_SickgivenPositive -> 0.98709677
AD17: MM | AG17: EV | AH17: =AJ16*AN15+AJ20*AQ20 -> 4.4631708 | AM17: EC | AN17: =AR14*AU14+AR18*AU18 -> 1047.5744 | AR17: P[MVD|S]
AD18: 1 | AR18: =p_MVDgivenS -> 0.9 | AT18: Cost | AU18: ='Costs & QALY'!G111 -> 966.22121 | AV18: QALY | AW18: ='Costs & QALY'!J39 -> 4.0132737
AG19: EC | AH19: =AJ16*AN17+AJ20*AL20 -> 1065.8603 | AJ19: P[H|+VE]
AJ20: =p_HealthyGivenPositive -> 0.012903226 | AK20: Cost | AL20: ='Costs & QALY'!C130 -> 2464.7259 | AN20: QALY | AQ20: ='Costs & QALY'!O63 -> 11.401127
AZ25: MM | BB25: Cost | BC25: ='Costs & QALY'!C111 -> 1779.7535 | BE25: QALY | BF25: ='Costs & QALY'!D44 -> 7.6053225 | BM25: Success
X26: Test +ve | AA26: EV | AB26: =IF(AH43>AH17,AH43,AH17) -> 5.1054064 | AZ26: 1 | BM26: =p_successSVDCABG -> 0.85 | BO26: Cost | BP26: ='Costs & QALY'!C83 -> 889.87677 | BR26: QALY | BS26: ='Costs & QALY'!D29 -> 8.163116
X27: =p_TestPositive -> 0.775 | AV27: Alive | AW27: EV | AX27: =IF(BC29>BF25,BC29,BF25) -> 7.8370636 | BE27: Alive | BJ27: EV | BK27: =BM26*BS26+BM30*BS30 -> 8.079447
AA28: EC | AB28: =IF(AH45>AH19,AH45,AH19) -> 5021.2885 | AV28: =p_AliveGivenSVDANG -> 0.9997 | BA28: CABG | BE28: =p_AliveGivenSVDCABG -> 0.97
AP29: SVD | AS29: EV | AT29: =AV28*AX27+AV35*BB35 -> 7.8347125 | AW29: EC | AX29: =IF(BA31>BC25,BA31,BC25) -> 4519.6575 | AZ29: CABG | BA29: =cost_CABG -> 3527 | BB29: EV | BC29: =BE28*BK27+BE32*BK32 -> 7.8370636 | BJ29: EC | BK29: =BM30*BP30+BM26*BP26 -> 1023.3583 | BM29: Fail
AA30: Optimal | AB30: =IF(AH43>AH17,AD43,AD17) -> ANG | AP30: =p_sVDgivenS -> 0.1 | AW30: Optimal | AX30: =IF(BC29>BF25,AZ29,AZ25) -> CABG | AZ30: 1 | BM30: =p_CABGfailSVD -> 0.15 | BO30: Cost | BP30: ='Costs & QALY'!C97 -> 1779.7535 | BR30: QALY | BS30: ='Costs & QALY'!D44 -> 7.6053225
AA31: NMB | AB31: =(AB26*base_threshold)-AB28 -> 148140.9 | AS31: EC | AT31: =AV28*AX29+AV35*AY35 -> 4518.3016 | AW31: NMB | AX31: =('The Decision Tree'!AX27*base_threshold)-'The Decision Tree'!AX29 -> 230592.25 | AZ31: EC+CABG | BA31: =BC31+BA29 -> 4519.6575 | BB31: EC | BC31: =BE28*BK29+BE32*BH32 -> 992.65754 | BE31: Dead
BE32: =Inputs!C46 -> 0.03 | BG32: Cost | BH32: 0 | BJ32: QALY | BK32: 0
AV34: Dead
AV35: =p_DeathGivenSVDANG -> 0.0003 | AX35: Cost | AY35: 0 | BA35: QALY | BB35: 0
AK37: ANG
AJ38: Test +ve | AK38: =cost_ANG -> 668 | AM38: EV | AN38: =AP30*AT29+AP43*AT42 -> 5.0231392 | AZ38: MM | BM38: Success
AJ39: =p_SickgivenPositive -> 0.98709677 | AZ39: 1 | BB39: Cost | BC39: ='Costs & QALY'!G111 -> 966.22121 | BE39: QALY | BF39: ='Costs & QALY'!J39 -> 4.0132737 | BM39: =p_CABGsucessMVD -> 0.7 | BO39: Cost | BP39: ='Costs & QALY'!G83 -> 889.87677 | BR39: QALY | BS39: ='Costs & QALY'!J29 -> 5.6021647
AJ40: EC+ANG | AK40: =AN40+AK38 -> 5045.982 | AM40: EC | AN40: =AP30*AT31+AP43*AT44 -> 4377.982 | AV40: Alive | AW40: EV | AX40: =IF(BC42>BF39,BC42,BF39) -> 4.7154576 | BE40: Alive | BJ40: EV | BK40: =BM39*BS39+BM43*BS43 -> 5.1254974
AV41: =p_AliveGivenMVDANG -> 0.999 | BA41: CABG | BE41: =p_AliveGiivenMVDCABG -> 0.92
AP42: MVD | AS42: EV | AT42: =AV41*AX40+AV48*BB48 -> 4.7107422 | AW42: EC | AX42: =IF(BA44>BC39,BA44,BC39) -> 4366.7577 | AZ42: CABG | BA42: =cost_CABG -> 3527 | BB42: EV | BC42: =BE41*BK40+BE45*BK45 -> 4.7154576 | BJ42: EC | BK42: =BM39*BP39+BM43*BP43 -> 912.7801 | BM42: Fail
R43: EST Cost | AD43: ANG | AE43: EC | AG43: EV | AH43: =AJ39*AN38+AJ57*AN56 -> 5.1054064 | AP43: =p_MVDgivenS -> 0.9 | AW43: Optimal | AX43: =IF(BC42>BF39,AZ42,AZ38) -> CABG | AZ43: 1 | BM43: =p_CABGfailMVD -> 0.3 | BO43: Cost | BP43: ='Costs & QALY'!G97 -> 966.22121 | BR43: QALY | BS43: ='Costs & QALY'!J39 -> 4.0132737
Q44: EST | R44: =cost_EST -> 53 | U44: EV | V44: =X27*AB26+X74*AB73 -> 5.573076 | AD44: 1 | AS44: EC | AT44: =AV41*AX42+AV48*AY48 -> 4362.3909 | AW44: NMB | AX44: =(AX40*base_threshold)-AX42 -> 137096.97 | AZ44: EC+CABG | BA44: =BC44+BA42 -> 4366.7577 | BB44: EC | BC44: =BE41*BK42+BE45*BH45 -> 839.75769 | BE44: Dead
Q45: 1 | AG45: EC | AH45: =AJ39*AK40+AJ57*AK58 -> 5021.2885 | BE45: =p_DaethGivenMVDCABG -> 0.08 | BG45: cost | BH45: 0 | BJ45: QALY | BK45: 0
Q46: EC+EST | R46: =V46+R44 -> 4307.7464 | U46: EC | V46: =X27*AB28+X74*AB75 -> 4254.7464
AV47: Dead
AV48: =p_DeathGivenMVDANG -> 0.001 | AX48: cost | AY48: 0 | BA48: QALY | BB48: 0
AV52: MM
AQ53: ANG COST | AV53: 1 | AX53: Cost | AY53: ='Costs & QALY'!C130 -> 2464.7259 | BA53: QALY | BB53: ='Costs & QALY'!O63 -> 11.401127
AP54: Alive | AQ54: 668 | AS54: EV | AT54: =IF(BB57>BB53,BB57,BB53) -> 11.401127
AK55: ANG | AP55: =Inputs!B54 -> 0.9998
AJ56: Test -ve | AK56: =cost_ANG -> 668 | AM56: EV | AN56: =AP55*AT54+AP59*AV59 -> 11.398847 | AP56: EC+ANG | AQ56: =AT56+AQ54 -> 3132.7259 | AS56: EC | AT56: =IF(AY57>AY53,AY57,AY53) -> 2464.7259 | AV56: No Treat
AJ57: =p_HealthyGivenPositive -> 0.012903226 | AS57: Optimal | AT57: =IF(BB53>BB57,AV52,AV56) -> No Treat | AV57: 1 | AX57: Cost | AY57: 0 | BA57: QALY | BB57: ='Costs & QALY'!O63 -> 11.401127
AJ58: EC+ANG | AK58: =AN58+AK56 -> 3132.233 | AM58: EC | AN58: =AP55*AT56+AP59*AS59 -> 2464.233 | AP58: Dead | AS58: NMB | AT58: =(AT54*base_threshold)-AT56 -> 339569.08
AP59: =Inputs!B48 -> 0.0002 | AR59: cost | AS59: 0 | AU59: QALY | AV59: 0
AP63: P[SVD|S] | AR63: Cost | AS63: ='Costs & QALY'!C111 -> 1779.7535 | AU63: QALY | AV63: ='Costs & QALY'!D44 -> 7.6053225
...

Sheet ICER Interpretation
B2: Strategy | C2: QALYs | D2: Cost
B3: No Treatment | C3: ='The Decision Tree'!V157 -> 2.6024556 | D3: ='The Decision Tree'!V159 -> 0
B4: Medical Management | C4: ='The Decision Tree'!V145 -> 5.0753434 | D4: ='The Decision Tree'!V147 -> 1189.2896
B5: Exercise Stress Test | C5: ='The Decision Tree'!V44 -> 5.573076 | D5: ='The Decision Tree'!R46 -> 4307.7464
B6: Angiography | C6: ='The Decision Tree'!V108 -> 5.6607099 | D6: ='The Decision Tree'!V110 -> 4854.5937
B9: ICER CALCULATION | F9: Base cost-effectiveness threshold
B10: MM vs No treatment | C10: =(D4-D3)/(C4-C3) -> 480.93148 | F10: 30000
B11: EST vs MM | C11: =(D5-D4)/(C5-C4) -> 6265.3262
B12: ANG vs EST | C12: =(D6-D5)/(C6-C5) -> 6240.1298 | F12: NMB @ threshold | G12: 30000
F13: No Treatment | G13: =(C3*F10)-D3 -> 78073.668
F14: Medical Management | G14: =(C4*base_threshold)-D4 -> 151071.01
B15: NMB @ threshold | C15: 25000 | F15: Exercise Stress Test | G15: =(C5*base_threshold)-D5 -> 162884.53
B16: No Treatment | C16: =(C3*$C$15)-D3 -> 65061.39 | F16: Angiography | G16: =(C6*base_threshold)-D6 -> 164966.7 | H16: Optimal | I16: =F16 -> Angiography
B17: Medical Management | C17: =(C4*$C$15)-D4 -> 125694.3
B18: Exercise Stress Test | C18: =(C5*$C$15)-D5 -> 135019.15
B19: Angiography | C19: =(C6*$C$15)-D6 -> 136663.15 | D19: Optimal | E19: =B19 -> Angiography
B22: NMB @ threshold | C22: 35000
B23: No Treatment | C23: =(C3*$C$22)-D3 -> 91085.946
B24: Medical Management | C24: =(C4*$C$22)-D4 -> 176447.73
B25: Exercise Stress Test | C25: =(C5*$C$22)-D5 -> 190749.91
B26: Angiography | C26: =(C6*$C$22)-D6 -> 193270.25 | D26: Optimal | E26: =B26 -> Angiography
B29: NMB @ threshold | C29: 10000
B30: No Treatment | C30: =(C3*$C$29)-D3 -> 26024.556
B31: Medical Management | C31: =(C4*$C$29)-D4 -> 49564.145
B32: Exercise Stress Test | C32: =(C5*$C$29)-D5 -> 51423.013
B33: Angiography | C33: =(C6*$C$29)-D6 -> 51752.506 | D33: Optimal | E33: =IF(C33>C32,B33,B32) -> Angiography
B36: NMB @ threshold | C36: 5000
B37: No Treatment | C37: =(C3*$C$36)-D4 -> 11822.988
B38: Medical Management | C38: =(C4*$C$36)-D5 -> 21068.971
B39: Exercise Stress Test | C39: =(C5*$C$36)-D6 -> 23010.786
B40: Angiography | C40: =(C6*$C$36)-D7 -> 28303.55 | D40: Optimal | E40: =IF(C40>C39,B40,B39) -> Angiography
B43: NMB @ threshold | C43: 15000
B44: No Treatment | C44: =(C3*$C$43)-D3 -> 39036.834
B45: Medical Management | C45: =(C4*$C$43)-D4 -> 74940.862
B46: Exercise Stress Test | C46: =(C5*$C$43)-D5 -> 79288.393
B47: Angiography | C47: =(C6*$C$43)-D6 -> 80056.055 | D47: Optimal | E47: =IF(C47>C46,B47,B46) -> Angiography
B50: NMB @ threshold | C50: 20000
B51: No Treatment | C51: =(C3*$C$50)-D3 -> 52049.112
B52: Medical Management | C52: =(C4*$C$50)-D4 -> 100317.58
B53: Exercise Stress Test | C53: =(C5*$C$50)-D5 -> 107153.77
...

Sheet 1-Way Sensitivity
C2: BASE CASE (£5,000 THRESHOLD) | I2: BASE CASE (£10,000 THRESHOLD) | O2: BASE CASE (£15,000 THRESHOLD) | U2: BASE CASE (£20,000 THRESHOLD) | AA2: BASE CASE (£25,000 THRESHOLD) | AG2: BASE CASE (£30,000 THRESHOLD) | AM2: BASE CASE (£35,000 THRESHOLD) | AS2: PERFECT INFORMATION (£10,000 THRESHOLD) | AY2: PERFECT INFORMATION (£20,000 THRESHOLD) | BF2: PERFECT INFORMATION (£30,000 THRESHOLD) | BM2: MVD-SVD BASE CASE (£10,000 THRESHOLD) | BS2: MVD-SVD BASE CASE (£20,000 THRESHOLD) | BY2: MVD-SVD BASE CASE (£30,000 THRESHOLD) | CE2: ANG SVD RISK BASE CASE (£10,000 THRESHOLD) | CK2: ANG SVD RISK BASE CASE (£20,000 THRESHOLD) | CQ2: ANG SVD-RISK BASE CASE (£30,000 THRESHOLD) | CW2: ANG MVD-RISK BASE CASE (£10,000 THRESHOLD) | DC2: ANG MVD-RISK BASE CASE (£20,000 THRESHOLD) | DI2: ANG MVD-RISK BASE CASE (£30,000 THRESHOLD) | DO2: ANG HEALTHY-RISK BASE CASE (£10,000 THRESHOLD) | DU2: ANG HEALTHY-RISK BASE CASE (£20,000 THRESHOLD) | EA2: ANG HEALTHY-RISK BASE CASE (£30,000 THRESHOLD) | EG2: CABG SVD-RISK BASE CASE (£10,000 THRESHOLD) | EM2: CABG SVD-RISK BASE CASE (£20,000 THRESHOLD) | ES2: CABG SVD-RISK BASE CASE (£30,000 THRESHOLD) | EY2: CABG MVD-RISK BASE CASE (£20,000 THRESHOLD) | FE2: CABG MVD-RISK BASE CASE (£10,000 THRESHOLD) | FK2: CABG MVD-RISK BASE CASE (£30,000 THRESHOLD) | FQ2: CABG SVD-SUCCESS BASE CASE (£10,000 THRESHOLD) | FW2: CABG SVD-SUCCESS BASE CASE (£20,000 THRESHOLD) | GC2: CABG SVD-SUCCESS BASE CASE (£30,000 THRESHOLD) | GI2: CABG MVD-SUCCESS BASE CASE (£10,000 THRESHOLD) | GO2: CABG MVD-SUCCESS BASE CASE (£20,000 THRESHOLD) | GU2: CABG MVD-SUCCESS BASE CASE (£30,000 THRESHOLD) | HA2: COST-EFFECTIVENESS THRESHOLD (P(s) = 0.9) | HG2: HEALTH DISCOUNT RATE BASE-CASE (£10,000 THR) | HM2: HEALTH DISCOUNT RATE BASE-CASE (£20,000 THR) | HS2: HEALTH DISCOUNT RATE BASE-CASE (£30,000 THR) | HY2: COST DISCOUNT RATE BASE-CASE (£10,000 THR) | IE2: COST DISCOUNT RATE BASE-CASE (£20,000 THR) | IK2: COST DISCOUNT RATE BASE-CASE (£30,000 THR)
D3: No Treat | E3: MM | F3: EST | G3: ANG | J3: No Treat | K3: MM | L3: EST | M3: ANG | P3: No Treat | Q3: MM | R3: EST | S3: ANG | V3: No Treat | W3: MM | X3: EST | Y3: ANG | AB3: No Treat | AC3: MM | AD3: EST | AE3: ANG | AH3: No Treat | AI3: MM | AJ3: EST | AK3: ANG | AN3: No Treat | AO3: MM | AP3: EST | AQ3: ANG | AS3: P(S) | AT3: No Treat | AU3: MM | AV3: Perfect EST | AW3: ANG | AY3: P(S) | AZ3: No Treat | BA3: MM | BB3: Base EST | BC3: Perfect EST | BD3: ANG | BF3: P(S) | BG3: No Treat | BH3: MM | BI3: Base EST | BJ3: Perfect EST | BK3: ANG | BM3: P(MVD) | BN3: EST | BO3: ANG | BP3: MM | BQ3: No Treat | BS3: P(MVD) | BT3: EST | BU3: ANG | BV3: MM | BW3: No Treat | BY3: P(MVD) | BZ3: EST | CA3: ANG | CB3: MM | CC3: No Treat | CE3: P(SVD Death) | CF3: EST | CG3: ANG | CH3: MM | CI3: No Treat | CK3: P(SVD Death) | CL3: EST | CM3: ANG | CN3: MM | CO3: No Treat | CQ3: P(SVD Death) | CR3: EST | CS3: ANG | CT3: MM | CU3: No Treat | CW3: P(MVD Death) | CX3: EST | CY3: ANG | CZ3: MM | DA3: No Treat | DC3: P(MVD Death) | DD3: EST | DE3: ANG | DF3: MM | DG3: No Treat | DI3: P(MVD Death) | DJ3: EST | DK3: ANG | DL3: MM | DM3: No Treat | DO3: P(H Death) | DP3: EST | DQ3: ANG | DR3: MM | DS3: No Treat | DU3: P(H Death) | DV3: EST | DW3: ANG | DX3: MM | DY3: No Treat | EA3: P(H Death) | EB3: EST | EC3: ANG | ED3: MM | EE3: No Treat | EG3: P(SVD ANG Death) | EH3: EST | EI3: ANG | EJ3: MM | EK3: No Treat | EM3: P(SVD ANG Death) | EN3: EST | EO3: ANG | EP3: MM | EQ3: No Treat | ES3: P(SVD ANG Death) | ET3: EST | EU3: ANG | EV3: MM | EW3: No Treat | EY3: P(MVD ANG Death) | EZ3: EST | FA3: ANG | FB3: MM | FC3: No Treat | FE3: P(MVD ANG Death) | FF3: EST | FG3: ANG | FH3: MM | FI3: No Treat | FK3: P(MVD ANG Death) | FL3: EST | FM3: ANG | FN3: MM | FO3: No Treat | FQ3: P(SVD SUCCESS) | FR3: EST | FS3: ANG | FT3: MM | FU3: No Treat | FW3: P(SVD SUCCESS) | FX3: EST | FY3: ANG | FZ3: MM | GA3: No Treat | GC3: P(SVD SUCCESS) | GD3: EST | GE3: ANG | GF3: MM | GG3: No Treat | GI3: P(MVD SUCCESS) | GJ3: EST | GK3: ANG | GL3: MM | GM3: No Treat | GO3: P(MVD SUCCESS) | GP3: EST | GQ3: ANG | GR3: MM | GS3: No Treat | GU3: P(MVD SUCCESS) | GV3: EST | GW3: ANG | GX3: MM | GY3: No Treat | HA3: CER | HB3: EST | HC3: ANG | HD3: MM | HE3: No Treat | HG3: Disc Rate | HH3: EST | HI3: ANG | HJ3: MM | HK3: No Treat | HM3: Disc Rate | HN3: EST | HO3: ANG | HP3: MM | HQ3: No Treat | HS3: Disc Rate | HT3: EST | HU3: ANG | HV3: MM | HW3: No Treat | HY3: Disc Rate | HZ3: EST | IA3: ANG | IB3: MM | IC3: No Treat | IE3: Disc Rate | IF3: EST | IG3: ANG | IH3: MM | II3: No Treat | IK3: Disc Rate | IL3: EST | IM3: ANG | IN3: MM | IO3: No Treat
C4: P(S) | D4: ='ICER Interpretation'!C37 -> 11822.988 | E4: ='ICER Interpretation'!C38 -> 21068.971 | F4: ='ICER Interpretation'!C39 -> 23010.786 | G4: ='ICER Interpretation'!C40 -> 28303.55 | I4: P(S) | J4: ='ICER Interpretation'!C30 -> 26024.556 | K4: ='ICER Interpretation'!C31 -> 49564.145 | L4: ='ICER Interpretation'!C32 -> 51423.013 | M4: ='ICER Interpretation'!C33 -> 51752.506 | O4: P(S) | P4: ='ICER Interpretation'!C44 -> 39036.834 | Q4: ='ICER Interpretation'!C45 -> 74940.862 | R4: ='ICER Interpretation'!C46 -> 79288.393 | S4: ='ICER Interpretation'!C47 -> 80056.055 | U4: P(S) | V4: ='ICER Interpretation'!C51 -> 52049.112 | W4: ='ICER Interpretation'!C52 -> 100317.58 | X4: ='ICER Interpretation'!C53 -> 107153.77 | Y4: ='ICER Interpretation'!C54 -> 108359.61 | AA4: P(S) | AB4: ='ICER Interpretation'!C16 -> 65061.39 | AC4: ='ICER Interpretation'!C17 -> 125694.3 | AD4: ='ICER Interpretation'!C18 -> 135019.15 | AE4: ='ICER Interpretation'!C19 -> 136663.15 | AG4: P(S) | AH4: ='ICER Interpretation'!G13 -> 78073.668 | AI4: ='ICER Interpretation'!G14 -> 151071.01 | AJ4: ='ICER Interpretation'!G15 -> 162884.53 | AK4: ='ICER Interpretation'!G16 -> 164966.7 | AM4: P(S) | AN4: ='ICER Interpretation'!C23 -> 91085.946 | AO4: ='ICER Interpretation'!C24 -> 176447.73 | AP4: ='ICER Interpretation'!C25 -> 190749.91 | AQ4: ='ICER Interpretation'!C26 -> 193270.25 | AS4: 0 | AT4: 114011.3 | AU4: 114011.3 | AV4: 113958.3 | AW4: 113320.5 | AY4: 0 | AZ4: 228022.6 | BA4: 228022.6 | BB4: 227898.24 | BC4: 227969.6 | BD4: 227309 | BF4: 0 | BG4: 342033.9 | BH4: 342033.9 | BI4: 341907.26 | BJ4: 341980.9 | BK4: 341297.49 | BM4: 0 | BN4: 77336.167 | BO4: 77176.788 | BP4: 78247.251 | BQ4: 49922.754 | BS4: 0 | BT4: 158939.8 | BU4: 159088.05 | BV4: 158096.28 | BW4: 99845.508 | BY4: 0 | BZ4: 240543.44 | CA4: 240999.31 | CB4: 237945.31 | CC4: 149768.26 | CE4: 0 | CF4: 51671.176 | CG4: 52000.91 | CH4: 49810.617 | CI4: 26024.556 | CK4: 0 | CL4: 107403.73 | CM4: 108610.13 | CN4: 100564.05 | CO4: 52049.112 | CQ4: 0 | CR4: 163136.29 | CS4: 165219.34 | CT4: 151317.49 | CU4: 78073.668 | CW4: 0 | CX4: 51698.94 | CY4: 52033.574 | CZ4: 49810.617 | DA4: 26024.556 | DC4: 0 | DD4: 107462.17 | DE4: 108678.87 | DF4: 100564.05 | DG4: 52049.112 | DI4: 0 | DJ4: 163225.39 | DK4: 165324.16 | DL4: 151317.49 | DM4: 78073.668 | DO4: 0 | DP4: 51669.709 | DQ4: 52001.196 | DR4: 49810.617 | DS4: 26024.556 | DU4: 0 | DV4: 107400.7 | DW4: 108610.58 | DX4: 100564.05 | DY4: 52049.112 | EA4: 0 | EB4: 163131.68 | EC4: 165219.96 | ED4: 151317.49 | EE4: 78073.668 | EG4: 0 | EH4: 51852.501 | EI4: 52214.233 | EJ4: 49810.617 | EK4: 26024.556 | EM4: 0 | EN4: 107768.63 | EO4: 109039.41 | EP4: 100564.05 | EQ4: 52049.112 | ES4: 0 | ET4: 163684.76 | EU4: 165864.59 | EV4: 151317.49 | EW4: 78073.668 | EY4: 0 | EZ4: 112990.62 | FA4: 115182.93 | FB4: 100564.05 | FC4: 52049.112 | FE4: 0 | FF4: 54439.556 | FG4: 55257.828 | FH4: 49810.617 | FI4: 26024.556 | FK4: 0 | FL4: 171541.68 | FM4: 175108.03 | FN4: 151317.49 | FO4: 78073.668 | FQ4: 0 | FR4: 51701.792 | FS4: 52036.929 | FT4: 49810.617 | FU4: 26024.556 | FW4: 0 | FX4: 107255.32 | FY4: 108435.52 | FZ4: 100564.05 | GA4: 52049.112 | GC4: 0 | GD4: 162808.85 | GE4: 164834.12 | GF4: 151317.49 | GG4: 78073.668 | GI4: 0 | GJ4: 51669.481 | GK4: 49068.594 | GL4: 49810.617 | GM4: 26024.556 | GO4: 0 | GP4: 107400.24 | GQ4: 99993.691 | GR4: 100564.05 | GS4: 52049.112 | GU4: 0 | GV4: 163131 | GW4: 150918.79 | GX4: 151317.49 | GY4: 78073.668 | HA4: 5000 | HB4: 23804.101 | HC4: 23695.366 | HD4: 24433.9 | HE4: 13012.278 | HG4: 0 | HH4: 60598.988 | HI4: 61079.254 | HJ4: 57881.983 | HK4: 30581 | HM4: 0 | HN4: 125259.25 | HO4: 126766.69 | HP4: 116706.78 | HQ4: 61162 | HS4: 0 | HT4: 189919.52 | HU4: 192454.13 | HV4: 175531.58 | HW4: 91743 | HY4: 0 | HZ4: 51537.156 | IA4: 51863.795 | IB4: 49694.134 | IC4: 26024.556 | IE4: 0 | IF4: 107267.92 | IG4: 108470.89 | IH4: 100447.57 | II4: 52049.112 | IK4: 0 | IL4: 162998.68 | IM4: 165077.99 | IN4: 151201 | IO4: 78073.668
C5: 0 | D5: 11822.988 | E5: 21068.971 | F5: 23010.786 | G5: 28303.55 | I5: 0 | J5: 26024.556 | K5: 49564.145 | L5: 51423.013 | M5: 51752.506 | O5: 0 | P5: 39036.834 | Q5: 74940.862 | R5: 79288.393 | S5: 80056.055 | U5: 0 | V5: 52049.112 | W5: 100317.58 | X5: 107153.77 | Y5: 108359.61 | AA5: 0 | AB5: 65061.39 | AC5: 125694.3 | AD5: 135019.15 | AE5: 136663.15 | AG5: 0 | AH5: 78073.668 | AI5: 151071.01 | AJ5: 162884.53 | AK5: 164966.7 | AM5: 0 | AN5: 91085.946 | AO5: 176447.73 | AP5: 190749.91 | AQ5: 193270.25 | AS5: 0.02 | AT5: 112056.05 | AU5: 112584.62 | AV5: 112581.78 | AW5: 111957.8 | AY5: 0.02 | AZ5: 224112.1 | BA5: 225190.19 | BB5: 225220.51 | BC5: 225317.48 | BD5: 224671.15 | BF5: 0.02 | BG5: 336168.15 | BH5: 337795.76 | BI5: 337934.45 | BJ5: 338053.19 | BK5: 337384.51 | BM5: 0.02 | BN5: 76765.797 | BO5: 76617.279 | BP5: 77615.326 | BQ5: 49391.683 | BS5: 0.02 | BT5: 157794.48 | BU5: 157966.22 | BV5: 156817.79 | BW5: 98783.366 | BY5: 0.02 | BZ5: 238823.16 | CA5: 239315.17 | CB5: 236020.25 | CC5: 148175.05 | CE5: 0.05 | CF5: 51388.696 | CG5: 51668.58 | CH5: 49810.617 | CI5: 26024.556 | CK5: 0.05 | CL5: 106821.49 | CM5: 107925.13 | CN5: 100564.05 | CO5: 52049.112 | CQ5: 0.05 | CR5: 162254.28 | CS5: 164181.68 | CT5: 151317.49 | CU5: 78073.668 | CW5: 0.05 | CX5: 50225.97 | CY5: 50300.667 | CZ5: 49810.617 | DA5: 26024.556 | DC5: 0.05 | DD5: 104365.9 | DE5: 105036.2 | DF5: 100564.05 | DG5: 52049.112 | DI5: 0.05 | DJ5: 158505.83 | DK5: 159771.74 | DL5: 151317.49 | DM5: 78073.668 | DO5: 0.05 | DP5: 51612.703 | DQ5: 51431.14 | DR5: 49810.617 | DS5: 26024.556 | DU5: 0.05 | DV5: 107286.69 | DW5: 107470.46 | DX5: 100564.05 | DY5: 52049.112 | EA5: 0.05 | EB5: 162960.67 | EC5: 163509.79 | ED5: 151317.49 | EE5: 78073.668 | EG5: 0.05 | EH5: 51547.468 | EI5: 51855.371 | EJ5: 49810.617 | EK5: 26024.556 | EM5: 0.05 | EN5: 107154.65 | EO5: 108317.08 | EP5: 100564.05 | EQ5: 52049.112 | ES5: 0.05 | ET5: 162761.83 | EU5: 164778.8 | EV5: 151317.49 | EW5: 78073.668 | EY5: 0.05 | EZ5: 109496.63 | FA5: 111072.36 | FB5: 100564.05 | FC5: 52049.112 | FE5: 0.05 | FF5: 52708.259 | FG5: 53221.008 | FH5: 49810.617 | FI5: 26024.556 | FK5: 0.05 | FL5: 166285 | FM5: 168923.71 | FN5: 151317.49 | FO5: 78073.668 | FQ5: 0.05 | FR5: 51701.792 | FS5: 52036.929 | FT5: 49810.617 | FU5: 26024.556 | FW5: 0.05 | FX5: 107255.32 | FY5: 108435.52 | FZ5: 100564.05 | GA5: 52049.112 | GC5: 0.05 | GD5: 162808.85 | GE5: 164834.12 | GF5: 151317.49 | GG5: 78073.668 | GI5: 0.05 | GJ5: 51669.481 | GK5: 49068.594 | GL5: 49810.617 | GM5: 26024.556 | GO5: 0.05 | GP5: 107400.24 | GQ5: 99993.691 | GR5: 100564.05 | GS5: 52049.112 | GU5: 0.05 | GV5: 163131 | GW5: 150918.79 | GX5: 151317.49 | GY5: 78073.668 | HA5: 10000 | HB5: 51669.481 | HC5: 51998.916 | HD5: 49810.617 | HE5: 26024.556 | HG5: 0.01 | HH5: 57815.865 | HI5: 58252.16 | HJ5: 55349.149 | HK5: 29124.47 | HM5: 0.01 | HN5: 119693.01 | HO5: 121112.5 | HP5: 111641.11 | HQ5: 58248.94 | HS5: 0.01 | HT5: 181570.15 | HU5: 183972.85 | HV5: 167933.08 | HW5: 87373.41 | HY5: 0.01 | HZ5: 51578.332 | IA5: 51905.957 | IB5: 49729.723 | IC5: 26024.556 | IE5: 0.01 | IF5: 107309.09 | IG5: 108513.06 | IH5: 100483.16 | II5: 52049.112 | IK5: 0.01 | IL5: 163039.85 | IM5: 165120.16 | IN5: 151236.59 | IO5: 78073.668
C6: 0.02 | D6: 11822.988 | E6: 21068.971 | F6: 23010.786 | G6: 28303.55 | I6: 0.02 | J6: 26024.556 | K6: 49564.145 | L6: 51423.013 | M6: 51752.506 | O6: 0.02 | P6: 39036.834 | Q6: 74940.862 | R6: 79288.393 | S6: 80056.055 | U6: 0.02 | V6: 52049.112 | W6: 100317.58 | X6: 107153.77 | Y6: 108359.61 | AA6: 0.02 | AB6: 65061.39 | AC6: 125694.3 | AD6: 135019.15 | AE6: 136663.15 | AG6: 0.02 | AH6: 78073.668 | AI6: 151071.01 | AJ6: 162884.53 | AK6: 164966.7 | AM6: 0.02 | AN6: 91085.946 | AO6: 176447.73 | AP6: 190749.91 | AQ6: 193270.25 | AS6: 0.04 | AT6: 110100.8 | AU6: 111157.94 | AV6: 111205.26 | AW6: 110595.09 | AY6: 0.04 | AZ6: 220201.6 | BA6: 222357.78 | BB6: 222542.77 | BC6: 222665.37 | BD6: 222033.31 | BF6: 0.04 | BG6: 330302.39 | BH6: 333557.62 | BI6: 333961.65 | BJ6: 334125.47 | BK6: 333471.52 | BM6: 0.04 | BN6: 76195.426 | BO6: 76057.771 | BP6: 76983.401 | BQ6: 48860.612 | BS6: 0.04 | BT6: 156649.15 | BU6: 156844.4 | BV6: 155539.29 | BW6: 97721.224 | BY6: 0.04 | BZ6: 237102.88 | CA6: 237631.03 | CB6: 234095.19 | CC6: 146581.84 | CE6: 0.1 | CF6: 51106.216 | CG6: 51336.251 | CH6: 49810.617 | CI6: 26024.556 | CK6: 0.1 | CL6: 106239.24 | CM6: 107240.13 | CN6: 100564.05 | CO6: 52049.112 | CQ6: 0.1 | CR6: 161372.26 | CS6: 163144.01 | CT6: 151317.49 | CU6: 78073.668 | CW6: 0.1 | CX6: 48752.999 | CY6: 48567.761 | CZ6: 49810.617 | DA6: 26024.556 | DC6: 0.1 | DD6: 101269.63 | DE6: 101393.53 | DF6: 100564.05 | DG6: 52049.112 | DI6: 0.1 | DJ6: 153786.27 | DK6: 154219.31 | DL6: 151317.49 | DM6: 78073.668 | DO6: 0.1 | DP6: 51555.698 | DQ6: 50861.083 | DR6: 49810.617 | DS6: 26024.556 | DU6: 0.1 | DV6: 107172.67 | DW6: 106330.35 | DX6: 100564.05 | DY6: 52049.112 | EA6: 0.1 | EB6: 162789.65 | EC6: 161799.62 | ED6: 151317.49 | EE6: 78073.668 | EG6: 0.1 | EH6: 51701.792 | EI6: 52036.929 | EJ6: 49810.617 | EK6: 26024.556 | EM6: 0.1 | EN6: 107255.32 | EO6: 108435.52 | EP6: 100564.05 | EQ6: 52049.112 | ES6: 0.1 | ET6: 162808.85 | EU6: 164834.12 | EV6: 151317.49 | EW6: 78073.668 | EY6: 0.1 | EZ6: 106002.65 | FA6: 106961.79 | FB6: 100564.05 | FC6: 52049.112 | FE6: 0.1 | FF6: 50976.962 | FG6: 51184.188 | FH6: 49810.617 | FI6: 26024.556 | FK6: 0.1 | FL6: 161028.33 | FM6: 162739.39 | FN6: 151317.49 | FO6: 78073.668 | FQ6: 0.1 | FR6: 51701.792 | FS6: 52036.929 | FT6: 49810.617 | FU6: 26024.556 | FW6: 0.1 | FX6: 107255.32 | FY6: 108435.52 | FZ6: 100564.05 | GA6: 52049.112 | GC6: 0.1 | GD6: 162808.85 | GE6: 164834.12 | GF6: 151317.49 | GG6: 78073.668 | GI6: 0.1 | GJ6: 51669.481 | GK6: 49068.594 | GL6: 49810.617 | GM6: 26024.556 | GO6: 0.1 | GP6: 107400.24 | GQ6: 99993.691 | GR6: 100564.05 | GS6: 52049.112 | GU6: 0.1 | GV6: 163131 | GW6: 150918.79 | GX6: 151317.49 | GY6: 78073.668 | HA6: 15000 | HB6: 79534.861 | HC6: 80302.465 | HD6: 75187.334 | HE6: 39036.834 | HG6: 0.02 | HH6: 55227.202 | HI6: 55620.115 | HJ6: 53007.318 | HK6: 27799.199 | HM6: 0.02 | HN6: 114515.68 | HO6: 115848.41 | HP6: 106957.45 | HQ6: 55598.397 | HS6: 0.02 | HT6: 173804.16 | HU6: 176076.71 | HV6: 160907.59 | HW6: 83397.596 | HY6: 0.02 | HZ6: 51616.694 | IA6: 51945.146 | IB6: 49763.399 | IC6: 26024.556 | IE6: 0.02 | IF6: 107347.45 | IG6: 108552.25 | IH6: 100516.83 | II6: 52049.112 | IK6: 0.02 | IL6: 163078.21 | IM6: 165159.35 | IN6: 151270.27 | IO6: 78073.668
C7: 0.04 | D7: 11822.988 | E7: 21068.971 | F7: 23010.786 | G7: 28303.55 | I7: 0.04 | J7: 26024.556 | K7: 49564.145 | L7: 51423.013 | M7: 51752.506 | O7: 0.04 | P7: 39036.834 | Q7: 74940.862 | R7: 79288.393 | S7: 80056.055 | U7: 0.04 | V7: 52049.112 | W7: 100317.58 | X7: 107153.77 | Y7: 108359.61 | AA7: 0.04 | AB7: 65061.39 | AC7: 125694.3 | AD7: 135019.15 | AE7: 136663.15 | AG7: 0.04 | AH7: 78073.668 | AI7: 151071.01 | AJ7: 162884.53 | AK7: 164966.7 | AM7: 0.04 | AN7: 91085.946 | AO7: 176447.73 | AP7: 190749.91 | AQ7: 193270.25 | AS7: 0.06 | AT7: 108145.55 | AU7: 109731.25 | AV7: 109828.75 | AW7: 109232.39 | AY7: 0.06 | AZ7: 216291.09 | BA7: 219525.36 | BB7: 219865.04 | BC7: 220013.25 | BD7: 219395.46 | BF7: 0.06 | BG7: 324436.64 | BH7: 329319.47 | BI7: 329988.84 | BJ7: 330197.76 | BK7: 329558.54 | BM7: 0.06 | BN7: 75625.055 | BO7: 75498.263 | BP7: 76351.476 | BQ7: 48329.541 | BS7: 0.06 | BT7: 155503.83 | BU7: 155722.58 | BV7: 154260.8 | BW7: 96659.082 | BY7: 0.06 | BZ7: 235382.61 | CA7: 235946.89 | CB7: 232170.12 | CC7: 144988.62 | CE7: 0.15 | CF7: 50823.736 | CG7: 51003.921 | CH7: 49810.617 | CI7: 26024.556 | CK7: 0.15 | CL7: 105656.99 | CM7: 106555.13 | CN7: 100564.05 | CO7: 52049.112 | CQ7: 0.15 | CR7: 160490.25 | CS7: 162106.35 | CT7: 151317.49 | CU7: 78073.668 | CW7: 0.15 | CX7: 47280.029 | CY7: 46834.854 | CZ7: 49810.617 | DA7: 26024.556 | DC7: 0.15 | DD7: 98173.365 | DE7: 97750.868 | DF7: 100564.05 | DG7: 52049.112 | DI7: 0.15 | DJ7: 149066.7 | DK7: 148666.88 | DL7: 151317.49 | DM7: 78073.668 | DO7: 0.15 | DP7: 51498.692 | DQ7: 50291.027 | DR7: 49810.617 | DS7: 26024.556 | DU7: 0.15 | DV7: 107058.66 | DW7: 105190.24 | DX7: 100564.05 | DY7: 52049.112 | EA7: 0.15 | EB7: 162618.63 | EC7: 160089.45 | ED7: 151317.49 | EE7: 78073.668 | EG7: 0.15 | EH7: 51701.792 | EI7: 52036.929 | EJ7: 49810.617 | EK7: 26024.556 | EM7: 0.15 | EN7: 107255.32 | EO7: 108435.52 | EP7: 100564.05 | EQ7: 52049.112 | ES7: 0.15 | ET7: 162808.85 | EU7: 164834.12 | EV7: 151317.49 | EW7: 78073.668 | EY7: 0.15 | EZ7: 102508.66 | FA7: 102851.22 | FB7: 100564.05 | FC7: 52049.112 | FE7: 0.15 | FF7: 49245.665 | FG7: 49147.368 | FH7: 49810.617 | FI7: 26024.556 | FK7: 0.15 | FL7: 155771.66 | FM7: 156555.06 | FN7: 151317.49 | FO7: 78073.668 | FQ7: 0.15 | FR7: 51701.792 | FS7: 52036.929 | FT7: 49810.617 | FU7: 26024.556 | FW7: 0.15 | FX7: 107255.32 | FY7: 108435.52 | FZ7: 100564.05 | GA7: 52049.112 | GC7: 0.15 | GD7: 162808.85 | GE7: 164834.12 | GF7: 151317.49 | GG7: 78073.668 | GI7: 0.15 | GJ7: 51669.481 | GK7: 49068.594 | GL7: 49810.617 | GM7: 26024.556 | GO7: 0.15 | GP7: 107400.24 | GQ7: 99993.691 | GR7: 100564.05 | GS7: 52049.112 | GU7: 0.15 | GV7: 163131 | GW7: 150918.79 | GX7: 151317.49 | GY7: 78073.668 | HA7: 20000 | HB7: 107400.24 | HC7: 108606.02 | HD7: 100564.05 | HE7: 52049.112 | HG7: 0.03 | HH7: 52814.747 | HI7: 53165.098 | HJ7: 50836.946 | HK7: 26589.911 | HM7: 0.03 | HN7: 109690.77 | HO7: 110938.38 | HP7: 102616.71 | HQ7: 53179.823 | HS7: 0.03 | HT7: 166566.8 | HU7: 168711.66 | HV7: 154396.47 | HW7: 79769.734 | HY7: 0.03 | HZ7: 51652.483 | IA7: 51981.622 | IB7: 49795.296 | IC7: 26024.556 | IE7: 0.03 | IF7: 107383.24 | IG7: 108588.72 | IH7: 100548.73 | II7: 52049.112 | IK7: 0.03 | IL7: 163114 | IM7: 165195.82 | IN7: 151302.16 | IO7: 78073.668
C8: 0.06 | D8: 11822.988 | E8: 21068.971 | F8: 23010.786 | G8: 28303.55 | I8: 0.06 | J8: 26024.556 | K8: 49564.145 | L8: 51423.013 | M8: 51752.506 | O8: 0.06 | P8: 39036.834 | Q8: 74940.862 | R8: 79288.393 | S8: 80056.055 | U8: 0.06 | V8: 52049.112 | W8: 100317.58 | X8: 107153.77 | Y8: 108359.61 | AA8: 0.06 | AB8: 65061.39 | AC8: 125694.3 | AD8: 135019.15 | AE8: 136663.15 | AG8: 0.06 | AH8: 78073.668 | AI8: 151071.01 | AJ8: 162884.53 | AK8: 164966.7 | AM8: 0.06 | AN8: 91085.946 | AO8: 176447.73 | AP8: 190749.91 | AQ8: 193270.25 | AS8: 0.08 | AT8: 106190.3 | AU8: 108304.57 | AV8: 108452.23 | AW8: 107869.69 | AY8: 0.08 | AZ8: 212380.59 | BA8: 216692.95 | BB8: 217187.31 | BC8: 217361.14 | BD8: 216757.62 | BF8: 0.08 | BG8: 318570.89 | BH8: 325081.33 | BI8: 326016.04 | BJ8: 326270.04 | BK8: 325645.55 | BM8: 0.08 | BN8: 75054.684 | BO8: 74938.755 | BP8: 75719.551 | BQ8: 47798.47 | BS8: 0.08 | BT8: 154358.51 | BU8: 154600.75 | BV8: 152982.31 | BW8: 95596.939 | BY8: 0.08 | BZ8: 233662.33 | CA8: 234262.76 | CB8: 230245.06 | CC8: 143395.41 | CE8: 0.2 | CF8: 50541.256 | CG8: 50671.592 | CH8: 49810.617 | CI8: 26024.556 | CK8: 0.2 | CL8: 105074.74 | CM8: 105870.14 | CN8: 100564.05 | CO8: 52049.112 | CQ8: 0.2 | CR8: 159608.23 | CS8: 161068.68 | CT8: 151317.49 | CU8: 78073.668 | CW8: 0.2 | CX8: 49757.617 | CY8: 45101.947 | CZ8: 49810.617 | DA8: 26024.556 | DC8: 0.2 | DD8: 100511.05 | DE8: 94108.201 | DF8: 100564.05 | DG8: 52049.112 | DI8: 0.2 | DJ8: 151264.49 | DK8: 143114.45 | DL8: 151317.49 | DM8: 78073.668 | DO8: 0.2 | DP8: 51441.687 | DQ8: 49720.971 | DR8: 49810.617 | DS8: 26024.556 | DU8: 0.2 | DV8: 106944.65 | DW8: 104050.12 | DX8: 100564.05 | DY8: 52049.112 | EA8: 0.2 | EB8: 162447.62 | EC8: 158379.28 | ED8: 151317.49 | EE8: 78073.668 | EG8: 0.2 | EH8: 51701.792 | EI8: 52036.929 | EJ8: 49810.617 | EK8: 26024.556 | EM8: 0.2 | EN8: 107255.32 | EO8: 108435.52 | EP8: 100564.05 | EQ8: 52049.112 | ES8: 0.2 | ET8: 162808.85 | EU8: 164834.12 | EV8: 151317.49 | EW8: 78073.668 | EY8: 0.2 | EZ8: 99014.677 | FA8: 98740.646 | FB8: 100564.05 | FC8: 52049.112 | FE8: 0.2 | FF8: 47514.368 | FG8: 47110.548 | FH8: 49810.617 | FI8: 26024.556 | FK8: 0.2 | FL8: 150514.99 | FM8: 150370.74 | FN8: 151317.49 | FO8: 78073.668 | FQ8: 0.2 | FR8: 51701.792 | FS8: 52036.929 | FT8: 49810.617 | FU8: 26024.556 | FW8: 0.2 | FX8: 107255.32 | FY8: 108435.52 | FZ8: 100564.05 | GA8: 52049.112 | GC8: 0.2 | GD8: 162808.85 | GE8: 164834.12 | GF8: 151317.49 | GG8: 78073.668 | GI8: 0.2 | GJ8: 51669.481 | GK8: 49068.594 | GL8: 49810.617 | GM8: 26024.556 | GO8: 0.2 | GP8: 107400.24 | GQ8: 99993.691 | GR8: 100564.05 | GS8: 52049.112 | GU8: 0.2 | GV8: 163131 | GW8: 150918.79 | GX8: 151317.49 | GY8: 78073.668 | HA8: 25000 | HB8: 135265.62 | HC8: 136909.56 | HD8: 125940.77 | HE8: 65061.39 | HG8: 0.04 | HH8: 50562.366 | HI8: 50871.153 | HJ8: 48820.898 | HK8: 25483.378 | HM8: 0.04 | HN8: 105186.01 | HO8: 106350.49 | HP8: 98584.612 | HQ8: 50966.755 | HS8: 0.04 | HT8: 159809.66 | HU8: 161829.83 | HV8: 148348.33 | HW8: 76450.133 | HY8: 0.04 | HZ8: 51685.916 | IA8: 52015.617 | IB8: 49825.539 | IC8: 26024.556 | IE8: 0.04 | IF8: 107416.68 | IG8: 108622.72 | IH8: 100578.97 | II8: 52049.112 | IK8: 0.04 | IL8: 163147.44 | IM8: 165229.82 | IN8: 151332.41 | IO8: 78073.668
C9: 0.08 | D9: 11822.988 | E9: 21068.971 | F9: 23010.786 | G9: 28303.55 | I9: 0.08 | J9: 26024.556 | K9: 49564.145 | L9: 51423.013 | M9: 51752.506 | O9: 0.08 | P9: 39036.834 | Q9: 74940.862 | R9: 79288.393 | S9: 80056.055 | U9: 0.08 | V9: 52049.112 | W9: 100317.58 | X9: 107153.77 | Y9: 108359.61 | AA9: 0.08 | AB9: 65061.39 | AC9: 125694.3 | AD9: 135019.15 | AE9: 136663.15 | AG9: 0.08 | AH9: 78073.668 | AI9: 151071.01 | AJ9: 162884.53 | AK9: 164966.7 | AM9: 0.08 | AN9: 91085.946 | AO9: 176447.73 | AP9: 190749.91 | AQ9: 193270.25 | AS9: 0.1 | AT9: 104235.04 | AU9: 106877.89 | AV9: 107075.71 | AW9: 106506.99 | AY9: 0.1 | AZ9: 208470.09 | BA9: 213860.54 | BB9: 214509.57 | BC9: 214709.02 | BD9: 214119.78 | BF9: 0.1 | BG9: 312705.13 | BH9: 320843.19 | BI9: 322043.23 | BJ9: 322342.33 | BK9: 321732.56 | BM9: 0.1 | BN9: 74484.313 | BO9: 74379.246 | BP9: 75087.625 | BQ9: 47267.399 | BS9: 0.1 | BT9: 153213.18 | BU9: 153478.93 | BV9: 151703.81 | BW9: 94534.797 | BY9: 0.1 | BZ9: 231942.06 | CA9: 232578.62 | CB9: 228320 | CC9: 141802.2 | CE9: 0.25 | CF9: 50258.776 | CG9: 50339.263 | CH9: 49810.617 | CI9: 26024.556 | CK9: 0.25 | CL9: 104492.5 | CM9: 105185.14 | CN9: 100564.05 | CO9: 52049.112 | CQ9: 0.25 | CR9: 158726.22 | CS9: 160031.01 | CT9: 151317.49 | CU9: 78073.668 | CW9: 0.25 | CX9: 49757.617 | CY9: 43369.041 | CZ9: 49810.617 | DA9: 26024.556 | DC9: 0.25 | DD9: 100511.05 | DE9: 90465.534 | DF9: 100564.05 | DG9: 52049.112 | DI9: 0.25 | DJ9: 151264.49 | DK9: 137562.03 | DL9: 151317.49 | DM9: 78073.668 | DO9: 0.25 | DP9: 51384.681 | DQ9: 49150.914 | DR9: 49810.617 | DS9: 26024.556 | DU9: 0.25 | DV9: 106830.64 | DW9: 102910.01 | DX9: 100564.05 | DY9: 52049.112 | EA9: 0.25 | EB9: 162276.6 | EC9: 156669.11 | ED9: 151317.49 | EE9: 78073.668 | EG9: 0.25 | EH9: 51701.792 | EI9: 52036.929 | EJ9: 49810.617 | EK9: 26024.556 | EM9: 0.25 | EN9: 107255.32 | EO9: 108435.52 | EP9: 100564.05 | EQ9: 52049.112 | ES9: 0.25 | ET9: 162808.85 | EU9: 164834.12 | EV9: 151317.49 | EW9: 78073.668 | EY9: 0.25 | EZ9: 100079.77 | FA9: 99993.691 | FB9: 100564.05 | FC9: 52049.112 | FE9: 0.25 | FF9: 49178.707 | FG9: 49068.594 | FH9: 49810.617 | FI9: 26024.556 | FK9: 0.25 | FL9: 150980.82 | FM9: 150918.79 | FN9: 151317.49 | FO9: 78073.668 | FQ9: 0.25 | FR9: 51701.792 | FS9: 52036.929 | FT9: 49810.617 | FU9: 26024.556 | FW9: 0.25 | FX9: 107255.32 | FY9: 108435.52 | FZ9: 100564.05 | GA9: 52049.112 | GC9: 0.25 | GD9: 162808.85 | GE9: 164834.12 | GF9: 151317.49 | GG9: 78073.668 | GI9: 0.25 | GJ9: 51669.481 | GK9: 46650.481 | GL9: 49810.617 | GM9: 26024.556 | GO9: 0.25 | GP9: 107400.24 | GQ9: 97934.722 | GR9: 100564.05 | GS9: 52049.112 | GU9: 0.25 | GV9: 163131 | GW9: 149218.96 | GX9: 151317.49 | GY9: 78073.668 | HA9: 30000 | HB9: 163131 | HC9: 165213.11 | HD9: 151317.49 | HE9: 78073.668 | HG9: 0.05 | HH9: 48455.757 | HI9: 48724.115 | HJ9: 46944.116 | HK9: 24468.107 | HM9: 0.05 | HN9: 100972.79 | HO9: 102056.41 | HP9: 94831.05 | HQ9: 48936.215 | HS9: 0.05 | HT9: 153489.83 | HU9: 155388.71 | HV9: 142717.98 | HW9: 73404.322 | HY9: 0.05 | HZ9: 51717.188 | IA9: 52047.343 | IB9: 49854.242 | IC9: 26024.556 | IE9: 0.05 | IF9: 107447.95 | IG9: 108654.44 | IH9: 100607.68 | II9: 52049.112 | IK9: 0.05 | IL9: 163178.71 | IM9: 165261.54 | IN9: 151361.11 | IO9: 78073.668
C10: 0.1 | D10: 11822.988 | E10: 21068.971 | F10: 23010.786 | G10: 28303.55 | I10: 0.1 | J10: 26024.556 | K10: 49564.145 | L10: 51423.013 | M10: 51752.506 | O10: 0.1 | P10: 39036.834 | Q10: 74940.862 | R10: 79288.393 | S10: 80056.055 | U10: 0.1 | V10: 52049.112 | W10: 100317.58 | X10: 107153.77 | Y10: 108359.61 | AA10: 0.1 | AB10: 65061.39 | AC10: 125694.3 | AD10: 135019.15 | AE10: 136663.15 | AG10: 0.1 | AH10: 78073.668 | AI10: 151071.01 | AJ10: 162884.53 | AK10: 164966.7 | AM10: 0.1 | AN10: 91085.946 | AO10: 176447.73 | AP10: 190749.91 | AQ10: 193270.25 | AS10: 0.12 | AT10: 102279.79 | AU10: 105451.21 | AV10: 105699.19 | AW10: 105144.29 | AY10: 0.12 | AZ10: 204559.59 | BA10: 211028.13 | BB10: 211831.84 | BC10: 212056.9 | BD10: 211481.93 | BF10: 0.12 | BG10: 306839.38 | BH10: 316605.05 | BI10: 318070.43 | BJ10: 318414.62 | BK10: 317819.58 | BM10: 0.12 | BN10: 73913.942 | BO10: 73819.738 | BP10: 74455.7 | BQ10: 46736.328 | BS10: 0.12 | BT10: 152067.86 | BU10: 152357.11 | BV10: 150425.32 | BW10: 93472.655 | BY10: 0.12 | BZ10: 230221.78 | CA10: 230894.48 | CB10: 226394.93 | CC10: 140208.98 | CE10: 0.3 | CF10: 49976.296 | CG10: 50006.933 | CH10: 49810.617 | CI10: 26024.556 | CK10: 0.3 | CL10: 103910.25 | CM10: 104500.14 | CN10: 100564.05 | CO10: 52049.112 | CQ10: 0.3 | CR10: 157844.2 | CS10: 158993.35 | CT10: 151317.49 | CU10: 78073.668 | CW10: 0.3 | CX10: 49757.617 | CY10: 41636.134 | CZ10: 49810.617 | DA10: 26024.556 | DC10: 0.3 | DD10: 100511.05 | DE10: 86822.867 | DF10: 100564.05 | DG10: 52049.112 | DI10: 0.3 | DJ10: 151264.49 | DK10: 132009.6 | DL10: 151317.49 | DM10: 78073.668 | DO10: 0.3 | DP10: 51327.675 | DQ10: 48580.858 | DR10: 49810.617 | DS10: 26024.556 | DU10: 0.3 | DV10: 106716.63 | DW10: 101769.9 | DX10: 100564.05 | DY10: 52049.112 | EA10: 0.3 | EB10: 162105.58 | EC10: 154958.94 | ED10: 151317.49 | EE10: 78073.668 | EG10: 0.3 | EH10: 51701.792 | EI10: 52036.929 | EJ10: 49810.617 | EK10: 26024.556 | EM10: 0.3 | EN10: 107255.32 | EO10: 108435.52 | EP10: 100564.05 | EQ10: 52049.112 | ES10: 0.3 | ET10: 162808.85 | EU10: 164834.12 | EV10: 151317.49 | EW10: 78073.668 | EY10: 0.3 | EZ10: 100079.77 | FA10: 99993.691 | FB10: 100564.05 | FC10: 52049.112 | FE10: 0.3 | FF10: 49178.707 | FG10: 49068.594 | FH10: 49810.617 | FI10: 26024.556 | FK10: 0.3 | FL10: 150980.82 | FM10: 150918.79 | FN10: 151317.49 | FO10: 78073.668 | FQ10: 0.3 | FR10: 51701.792 | FS10: 52036.929 | FT10: 49810.617 | FU10: 26024.556 | FW10: 0.3 | FX10: 107255.32 | FY10: 108435.52 | FZ10: 100564.05 | GA10: 52049.112 | GC10: 0.3 | GD10: 162808.85 | GE10: 164834.12 | GF10: 151317.49 | GG10: 78073.668 | GI10: 0.3 | GJ10: 51669.481 | GK10: 47244.752 | GL10: 49810.617 | GM10: 26024.556 | GO10: 0.3 | GP10: 107400.24 | GQ10: 99120.421 | GR10: 100564.05 | GS10: 52049.112 | GU10: 0.3 | GV10: 163131 | GW10: 150996.09 | GX10: 151317.49 | GY10: 78073.668 | HA10: 35000 | HB10: 190996.38 | HC10: 193516.66 | HD10: 176694.2 | HE10: 91085.946 | HG10: 0.06 | HH10: 46482.206 | HI10: 46711.368 | HJ10: 45193.333 | HK10: 23534.101 | HM10: 0.06 | HN10: 97025.69 | HO10: 98030.919 | HP10: 91329.484 | HQ10: 47068.203 | HS10: 0.06 | HT10: 147569.17 | HU10: 149350.47 | HV10: 137465.63 | HW10: 70602.304 | HY10: 0.06 | HZ10: 51746.478 | IA10: 52076.99 | IB10: 49881.508 | IC10: 26024.556 | IE10: 0.06 | IF10: 107477.24 | IG10: 108684.09 | IH10: 100634.94 | II10: 52049.112 | IK10: 0.06 | IL10: 163208 | IM10: 165291.19 | IN10: 151388.38 | IO10: 78073.668
C11: 0.12 | D11: 11822.988 | E11: 21068.971 | F11: 23010.786 | G11: 28303.55 | I11: 0.12 | J11: 26024.556 | K11: 49564.145 | L11: 51423.013 | M11: 51752.506 | O11: 0.12 | P11: 39036.834 | Q11: 74940.862 | R11: 79288.393 | S11: 80056.055 | U11: 0.12 | V11: 52049.112 | W11: 100317.58 | X11: 107153.77 | Y11: 108359.61 | AA11: 0.12 | AB11: 65061.39 | AC11: 125694.3 | AD11: 135019.15 | AE11: 136663.15 | AG11: 0.12 | AH11: 78073.668 | AI11: 151071.01 | AJ11: 162884.53 | AK11: 164966.7 | AM11: 0.12 | AN11: 91085.946 | AO11: 176447.73 | AP11: 190749.91 | AQ11: 193270.25 | AS11: 0.14 | AT11: 100324.54 | AU11: 104024.53 | AV11: 104322.68 | AW11: 103781.59 | AY11: 0.14 | AZ11: 200649.08 | BA11: 208195.72 | BB11: 209154.11 | BC11: 209404.79 | BD11: 208844.09 | BF11: 0.14 | BG11: 300973.63 | BH11: 312366.9 | BI11: 314097.62 | BJ11: 314486.9 | BK11: 313906.59 | BM11: 0.14 | BN11: 73343.572 | BO11: 73260.23 | BP11: 73823.775 | BQ11: 46205.257 | BS11: 0.14 | BT11: 150922.54 | BU11: 151235.29 | BV11: 149146.82 | BW11: 92410.513 | BY11: 0.14 | BZ11: 228501.5 | CA11: 229210.34 | CB11: 224469.87 | CC11: 138615.77 | CE11: 0.35 | CF11: 49693.816 | CG11: 49674.604 | CH11: 49810.617 | CI11: 26024.556 | CK11: 0.35 | CL11: 103328 | CM11: 103815.14 | CN11: 100564.05 | CO11: 52049.112 | CQ11: 0.35 | CR11: 156962.19 | CS11: 157955.68 | CT11: 151317.49 | CU11: 78073.668 | CW11: 0.35 | CX11: 49757.617 | CY11: 39903.227 | CZ11: 49810.617 | DA11: 26024.556 | DC11: 0.35 | DD11: 100511.05 | DE11: 83180.2 | DF11: 100564.05 | DG11: 52049.112 | DI11: 0.35 | DJ11: 151264.49 | DK11: 126457.17 | DL11: 151317.49 | DM11: 78073.668 | DO11: 0.35 | DP11: 51270.67 | DQ11: 48010.801 | DR11: 49810.617 | DS11: 26024.556 | DU11: 0.35 | DV11: 106602.62 | DW11: 100629.79 | DX11: 100564.05 | DY11: 52049.112 | EA11: 0.35 | EB11: 161934.57 | EC11: 153248.77 | ED11: 151317.49 | EE11: 78073.668 | EG11: 0.35 | EH11: 51701.792 | EI11: 52036.929 | EJ11: 49810.617 | EK11: 26024.556 | EM11: 0.35 | EN11: 107255.32 | EO11: 108435.52 | EP11: 100564.05 | EQ11: 52049.112 | ES11: 0.35 | ET11: 162808.85 | EU11: 164834.12 | EV11: 151317.49 | EW11: 78073.668 | EY11: 0.35 | EZ11: 100079.77 | FA11: 99993.691 | FB11: 100564.05 | FC11: 52049.112 | FE11: 0.35 | FF11: 49178.707 | FG11: 49068.594 | FH11: 49810.617 | FI11: 26024.556 | FK11: 0.35 | FL11: 150980.82 | FM11: 150918.79 | FN11: 151317.49 | FO11: 78073.668 | FQ11: 0.35 | FR11: 51701.792 | FS11: 52036.929 | FT11: 49810.617 | FU11: 26024.556 | FW11: 0.35 | FX11: 107255.32 | FY11: 108435.52 | FZ11: 100564.05 | GA11: 52049.112 | GC11: 0.35 | GD11: 162808.85 | GE11: 164834.12 | GF11: 151317.49 | GG11: 78073.668 | GI11: 0.35 | GJ11: 51669.481 | GK11: 47839.022 | GL11: 49810.617 | GM11: 26024.556 | GO11: 0.35 | GP11: 107400.24 | GQ11: 100306.12 | GR11: 100564.05 | GS11: 52049.112 | GU11: 0.35 | GV11: 163131 | GW11: 152773.22 | GX11: 151317.49 | GY11: 78073.668 | HA11: 40000 | HB11: 218861.76 | HC11: 221820.21 | HD11: 202070.92 | HE11: 104098.22 | HG11: 0.07 | HH11: 44630.378 | HI11: 44821.647 | HJ11: 43556.827 | HK11: 22672.635 | HM11: 0.07 | HN11: 93322.035 | HO11: 94251.478 | HP11: 88056.471 | HQ11: 45345.271 | HS11: 0.07 | HT11: 142013.69 | HU11: 143681.31 | HV11: 132556.11 | HW11: 68017.906 | HY11: 0.07 | HZ11: 51773.943 | IA11: 52104.728 | IB11: 49907.432 | IC11: 26024.556 | IE11: 0.07 | IF11: 107504.7 | IG11: 108711.83 | IH11: 100660.87 | II11: 52049.112 | IK11: 0.07 | IL11: 163235.46 | IM11: 165318.93 | IN11: 151414.3 | IO11: 78073.668
C12: 0.14 | D12: 11822.988 | E12: 21068.971 | F12: 23010.786 | G12: 28303.55 | I12: 0.14 | J12: 26024.556 | K12: 49564.145 | L12: 51423.013 | M12: 51752.506 | O12: 0.14 | P12: 39036.834 | Q12: 74940.862 | R12: 79288.393 | S12: 80056.055 | U12: 0.14 | V12: 52049.112 | W12: 100317.58 | X12: 107153.77 | Y12: 108359.61 | AA12: 0.14 | AB12: 65061.39 | AC12: 125694.3 | AD12: 135019.15 | AE12: 136663.15 | AG12: 0.14 | AH12: 78073.668 | AI12: 151071.01 | AJ12: 162884.53 | AK12: 164966.7 | AM12: 0.14 | AN12: 91085.946 | AO12: 176447.73 | AP12: 190749.91 | AQ12: 193270.25 | AS12: 0.16 | AT12: 98369.291 | AU12: 102597.85 | AV12: 102946.16 | AW12: 102418.88 | AY12: 0.16 | AZ12: 196738.58 | BA12: 205363.3 | BB12: 206476.38 | BC12: 206752.67 | BD12: 206206.25 | BF12: 0.16 | BG12: 295107.87 | BH12: 308128.76 | BI12: 310124.82 | BJ12: 310559.19 | BK12: 309993.61 | BM12: 0.16 | BN12: 72773.201 | BO12: 72700.721 | BP12: 73191.85 | BQ12: 45674.185 | BS12: 0.16 | BT12: 149777.21 | BU12: 150113.46 | BV12: 147868.33 | BW12: 91348.371 | BY12: 0.16 | BZ12: 226781.23 | CA12: 227526.21 | CB12: 222544.81 | CC12: 137022.56 | CE12: 0.4 | CF12: 49411.336 | CG12: 49342.274 | CH12: 49810.617 | CI12: 26024.556 | CK12: 0.4 | CL12: 102745.75 | CM12: 103130.15 | CN12: 100564.05 | CO12: 52049.112 | CQ12: 0.4 | CR12: 156080.17 | CS12: 156918.02 | CT12: 151317.49 | CU12: 78073.668 | CW12: 0.4 | CX12: 49757.617 | CY12: 38170.321 | CZ12: 49810.617 | DA12: 26024.556 | DC12: 0.4 | DD12: 100511.05 | DE12: 79537.533 | DF12: 100564.05 | DG12: 52049.112 | DI12: 0.4 | DJ12: 151264.49 | DK12: 120904.74 | DL12: 151317.49 | DM12: 78073.668 | DO12: 0.4 | DP12: 51213.664 | DQ12: 47440.745 | DR12: 49810.617 | DS12: 26024.556 | DU12: 0.4 | DV12: 106488.61 | DW12: 99489.674 | DX12: 100564.05 | DY12: 52049.112 | EA12: 0.4 | EB12: 161763.55 | EC12: 151538.6 | ED12: 151317.49 | EE12: 78073.668 | EG12: 0.4 | EH12: 51701.792 | EI12: 52036.929 | EJ12: 49810.617 | EK12: 26024.556 | EM12: 0.4 | EN12: 107255.32 | EO12: 108435.52 | EP12: 100564.05 | EQ12: 52049.112 | ES12: 0.4 | ET12: 162808.85 | EU12: 164834.12 | EV12: 151317.49 | EW12: 78073.668 | EY12: 0.4 | EZ12: 100079.77 | FA12: 99993.691 | FB12: 100564.05 | FC12: 52049.112 | FE12: 0.4 | FF12: 49178.707 | FG12: 49068.594 | FH12: 49810.617 | FI12: 26024.556 | FK12: 0.4 | FL12: 150980.82 | FM12: 150918.79 | FN12: 151317.49 | FO12: 78073.668 | FQ12: 0.4 | FR12: 51701.792 | FS12: 52036.929 | FT12: 49810.617 | FU12: 26024.556 | FW12: 0.4 | FX12: 107255.32 | FY12: 108435.52 | FZ12: 100564.05 | GA12: 52049.112 | GC12: 0.4 | GD12: 162808.85 | GE12: 164834.12 | GF12: 151317.49 | GG12: 78073.668 | GI12: 0.4 | GJ12: 51669.481 | GK12: 48433.293 | GL12: 49810.617 | GM12: 26024.556 | GO12: 0.4 | GP12: 107400.24 | GQ12: 101491.82 | GR12: 100564.05 | GS12: 52049.112 | GU12: 0.4 | GV12: 163131 | GW12: 154550.35 | GX12: 151317.49 | GY12: 78073.668 | HA12: 45000 | HB12: 246727.14 | HC12: 250123.76 | HD12: 227447.64 | HE12: 117110.5 | HG12: 0.08 | HH12: 42890.144 | HI12: 43044.869 | HJ12: 42024.216 | HK12: 21876.082 | HM12: 0.08 | HN12: 89841.566 | HO12: 90697.922 | HP12: 84991.249 | HQ12: 43752.164 | HS12: 0.08 | HT12: 136792.99 | HU12: 138350.97 | HV12: 127958.28 | HW12: 65628.245 | HY12: 0.08 | HZ12: 51799.731 | IA12: 52130.712 | IB12: 49932.102 | IC12: 26024.556 | IE12: 0.08 | IF12: 107530.49 | IG12: 108737.81 | IH12: 100685.54 | II12: 52049.112 | IK12: 0.08 | IL12: 163261.25 | IM12: 165344.91 | IN12: 151438.97 | IO12: 78073.668
C13: 0.16 | D13: 11822.988 | E13: 21068.971 | F13: 23010.786 | G13: 28303.55 | I13: 0.16 | J13: 26024.556 | K13: 49564.145 | L13: 51423.013 | M13: 51752.506 | O13: 0.16 | P13: 39036.834 | Q13: 74940.862 | R13: 79288.393 | S13: 80056.055 | U13: 0.16 | V13: 52049.112 | W13: 100317.58 | X13: 107153.77 | Y13: 108359.61 | AA13: 0.16 | AB13: 65061.39 | AC13: 125694.3 | AD13: 135019.15 | AE13: 136663.15 | AG13: 0.16 | AH13: 78073.668 | AI13: 151071.01 | AJ13: 162884.53 | AK13: 164966.7 | AM13: 0.16 | AN13: 91085.946 | AO13: 176447.73 | AP13: 190749.91 | AQ13: 193270.25 | AS13: 0.18 | AT13: 96414.04 | AU13: 101171.16 | AV13: 101569.64 | AW13: 101056.18 | AY13: 0.18 | AZ13: 192828.08 | BA13: 202530.89 | BB13: 203798.64 | BC13: 204100.56 | BD13: 203568.4 | BF13: 0.18 | BG13: 289242.12 | BH13: 303890.62 | BI13: 306152.01 | BJ13: 306631.47 | BK13: 306080.62 | BM13: 0.18 | BN13: 72202.83 | BO13: 72141.213 | BP13: 72559.925 | BQ13: 45143.114 | BS13: 0.18 | BT13: 148631.89 | BU13: 148991.64 | BV13: 146589.84 | BW13: 90286.229 | BY13: 0.18 | BZ13: 225060.95 | CA13: 225842.07 | CB13: 220619.75 | CC13: 135429.34 | CE13: 0.45 | CF13: 49128.856 | CG13: 49009.945 | CH13: 49810.617 | CI13: 26024.556 | CK13: 0.45 | CL13: 102163.51 | CM13: 102445.15 | CN13: 100564.05 | CO13: 52049.112 | CQ13: 0.45 | CR13: 155198.15 | CS13: 155880.35 | CT13: 151317.49 | CU13: 78073.668 | CW13: 0.45 | CX13: 49757.617 | CY13: 36437.414 | CZ13: 49810.617 | DA13: 26024.556 | DC13: 0.45 | DD13: 100511.05 | DE13: 75894.866 | DF13: 100564.05 | DG13: 52049.112 | DI13: 0.45 | DJ13: 151264.49 | DK13: 115352.32 | DL13: 151317.49 | DM13: 78073.668 | DO13: 0.45 | DP13: 51156.658 | DQ13: 46870.689 | DR13: 49810.617 | DS13: 26024.556 | DU13: 0.45 | DV13: 106374.6 | DW13: 98349.561 | DX13: 100564.05 | DY13: 52049.112 | EA13: 0.45 | EB13: 161592.53 | EC13: 149828.43 | ED13: 151317.49 | EE13: 78073.668 | EG13: 0.45 | EH13: 51701.792 | EI13: 52036.929 | EJ13: 49810.617 | EK13: 26024.556 | EM13: 0.45 | EN13: 107255.32 | EO13: 108435.52 | EP13: 100564.05 | EQ13: 52049.112 | ES13: 0.45 | ET13: 162808.85 | EU13: 164834.12 | EV13: 151317.49 | EW13: 78073.668 | EY13: 0.45 | EZ13: 100079.77 | FA13: 99993.691 | FB13: 100564.05 | FC13: 52049.112 | FE13: 0.45 | FF13: 49178.707 | FG13: 49068.594 | FH13: 49810.617 | FI13: 26024.556 | FK13: 0.45 | FL13: 150980.82 | FM13: 150918.79 | FN13: 151317.49 | FO13: 78073.668 | FQ13: 0.45 | FR13: 51477.561 | FS13: 51773.127 | FT13: 49810.617 | FU13: 26024.556 | FW13: 0.45 | FX13: 107042.81 | FY13: 108185.5 | FZ13: 100564.05 | GA13: 52049.112 | GC13: 0.45 | GD13: 162608.05 | GE13: 164597.88 | GF13: 151317.49 | GG13: 78073.668 | GI13: 0.45 | GJ13: 51669.481 | GK13: 49027.563 | GL13: 49810.617 | GM13: 26024.556 | GO13: 0.45 | GP13: 107400.24 | GQ13: 102677.52 | GR13: 100564.05 | GS13: 52049.112 | GU13: 0.45 | GV13: 163131 | GW13: 156327.47 | GX13: 151317.49 | GY13: 78073.668 | HA13: 50000 | HB13: 274592.52 | HC13: 278427.31 | HD13: 252824.35 | HE13: 130122.78 | HG13: 0.09 | HH13: 41252.426 | HI13: 41371.982 | HJ13: 40586.283 | HK13: 21137.756 | HM13: 0.09 | HN13: 86566.13 | HO13: 87352.147 | HP13: 82115.384 | HQ13: 42275.513 | HS13: 0.09 | HT13: 131879.84 | HU13: 133332.31 | HV13: 123644.48 | HW13: 63413.269 | HY13: 0.09 | HZ13: 51823.971 | IA13: 52155.084 | IB13: 49955.598 | IC13: 26024.556 | IE13: 0.09 | IF13: 107554.73 | IG13: 108762.18 | IH13: 100709.03 | II13: 52049.112 | IK13: 0.09 | IL13: 163285.49 | IM13: 165369.28 | IN13: 151462.47 | IO13: 78073.668
C14: 0.18 | D14: 11822.988 | E14: 21068.971 | F14: 23010.786 | G14: 28303.55 | I14: 0.18 | J14: 26024.556 | K14: 49564.145 | L14: 51423.013 | M14: 51752.506 | O14: 0.18 | P14: 39036.834 | Q14: 74940.862 | R14: 79288.393 | S14: 80056.055 | U14: 0.18 | V14: 52049.112 | W14: 100317.58 | X14: 107153.77 | Y14: 108359.61 | AA14: 0.18 | AB14: 65061.39 | AC14: 125694.3 | AD14: 135019.15 | AE14: 136663.15 | AG14: 0.18 | AH14: 78073.668 | AI14: 151071.01 | AJ14: 162884.53 | AK14: 164966.7 | AM14: 0.18 | AN14: 91085.946 | AO14: 176447.73 | AP14: 190749.91 | AQ14: 193270.25 | AS14: 0.2 | AT14: 94458.789 | AU14: 99744.483 | AV14: 100193.12 | AW14: 99693.481 | AY14: 0.2 | AZ14: 188917.58 | BA14: 199698.48 | BB14: 201120.91 | BC14: 201448.44 | BD14: 200930.56 | BF14: 0.2 | BG14: 283376.37 | BH14: 299652.48 | BI14: 302179.21 | BJ14: 302703.76 | BK14: 302167.63 | BM14: 0.2 | BN14: 71632.459 | BO14: 71581.705 | BP14: 71927.999 | BQ14: 44612.043 | BS14: 0.2 | BT14: 147486.57 | BU14: 147869.82 | BV14: 145311.34 | BW14: 89224.087 | BY14: 0.2 | BZ14: 223340.67 | CA14: 224157.93 | CB14: 218694.68 | CC14: 133836.13 | CE14: 0.5 | CF14: 48846.376 | CG14: 48677.616 | CH14: 49810.617 | CI14: 26024.556 | CK14: 0.5 | CL14: 101581.26 | CM14: 101760.15 | CN14: 100564.05 | CO14: 52049.112 | CQ14: 0.5 | CR14: 154316.14 | CS14: 154842.69 | CT14: 151317.49 | CU14: 78073.668 | CW14: 0.5 | CX14: 49757.617 | CY14: 34704.507 | CZ14: 49810.617 | DA14: 26024.556 | DC14: 0.5 | DD14: 100511.05 | DE14: 72252.199 | DF14: 100564.05 | DG14: 52049.112 | DI14: 0.5 | DJ14: 151264.49 | DK14: 109799.89 | DL14: 151317.49 | DM14: 78073.668 | DO14: 0.5 | DP14: 51099.653 | DQ14: 46300.632 | DR14: 49810.617 | DS14: 26024.556 | DU14: 0.5 | DV14: 106260.58 | DW14: 97209.449 | DX14: 100564.05 | DY14: 52049.112 | EA14: 0.5 | EB14: 161421.52 | EC14: 148118.26 | ED14: 151317.49 | EE14: 78073.668 | EG14: 0.5 | EH14: 51701.792 | EI14: 52036.929 | EJ14: 49810.617 | EK14: 26024.556 | EM14: 0.5 | EN14: 107255.32 | EO14: 108435.52 | EP14: 100564.05 | EQ14: 52049.112 | ES14: 0.5 | ET14: 162808.85 | EU14: 164834.12 | EV14: 151317.49 | EW14: 78073.668 | EY14: 0.5 | EZ14: 100079.77 | FA14: 99993.691 | FB14: 100564.05 | FC14: 52049.112 | FE14: 0.5 | FF14: 49178.707 | FG14: 49068.594 | FH14: 49810.617 | FI14: 26024.556 | FK14: 0.5 | FL14: 150980.82 | FM14: 150918.79 | FN14: 151317.49 | FO14: 78073.668 | FQ14: 0.5 | FR14: 51501.551 | FS14: 51801.351 | FT14: 49810.617 | FU14: 26024.556 | FW14: 0.5 | FX14: 107087.49 | FY14: 108238.07 | FZ14: 100564.05 | GA14: 52049.112 | GC14: 0.5 | GD14: 162673.42 | GE14: 164674.78 | GF14: 151317.49 | GG14: 78073.668 | GI14: 0.5 | GJ14: 51669.481 | GK14: 49621.834 | GL14: 49810.617 | GM14: 26024.556 | GO14: 0.5 | GP14: 107400.24 | GQ14: 103863.22 | GR14: 100564.05 | GS14: 52049.112 | GU14: 0.5 | GV14: 163131 | GW14: 158104.6 | GX14: 151317.49 | GY14: 78073.668 | HA14: 55000 | HB14: 302457.9 | HC14: 306730.86 | HD14: 278201.07 | HE14: 143135.06 | HG14: 0.1 | HH14: 39709.07 | HI14: 39794.841 | HJ14: 39234.826 | HK14: 20451.788 | HM14: 0.1 | HN14: 83479.419 | HO14: 84197.865 | HP14: 79412.469 | HQ14: 40903.575 | HS14: 0.1 | HT14: 127249.77 | HU14: 128600.89 | HV14: 119590.11 | HW14: 61355.363 | HY14: 0.1 | HZ14: 51846.783 | IA14: 52177.969 | IB14: 49977.995 | IC14: 26024.556 | IE14: 0.1 | IF14: 107577.54 | IG14: 108785.07 | IH14: 100731.43 | II14: 52049.112 | IK14: 0.1 | IL14: 163308.3 | IM14: 165392.17 | IN14: 151484.86 | IO14: 78073.668
